Workbook

Sheet Resumen
A1: RESUMEN DE PRESUPUESTO
A2: DERRIBO Y VIVIENDA DE NUEVA PLANTA · C. ANCHA 34, LODOSA
A3: Presupuesto conjunto (derribo + obra nueva) · propuesta de octubre de 2026, con las mediciones del modelo BIM del 14-oct y la opción 3 de cubiertas del IFC final (21-oct); con la estructura del ingeniero (23-oct) y el IFC del 24-oct (muros bajo rasante y revoco)
A5: Capítulo | B5: Resumen | C5: Importe | D5: %
A6: D | B6: DERRIBO
A7: D01 | B7: ACTUACIONES PREVIAS, PROTECCIÓN Y APEO DE MEDIANERAS | C7: =Presupuesto!K18 -> 953.2 | D7: =IF($C$50=0,0,C7/$C$50) -> 0.0023838207
A8: D02 | B8: DEMOLICIONES | C8: =Presupuesto!K61 -> 9292.58 | D8: =IF($C$50=0,0,C8/$C$50) -> 0.023239451
A9: D03 | B9: GESTIÓN DE RESIDUOS | C9: =Presupuesto!K88 -> 9643.5 | D9: =IF($C$50=0,0,C9/$C$50) -> 0.024117054
A10: D04 | B10: SEGURIDAD Y SALUD | C10: =Presupuesto!K112 -> 1450 | D10: =IF($C$50=0,0,C10/$C$50) -> 0.0036262485
B11: PEM DERRIBO | C11: =C7+C8+C9+C10 -> 21339.28
A13: ON | B13: OBRA NUEVA
A14: 01 | B14: CONSIDERACIONES PREVIAS | C14: =Presupuesto!K141 -> 1530.9 | D14: =IF($C$50=0,0,C14/$C$50) -> 0.0038285682
A15: 02 | B15: TRABAJOS PREVIOS Y DEMOLICIÓN | C15: =Presupuesto!K148 -> 0 | D15: =IF($C$50=0,0,C15/$C$50) -> 0
A16: 03 | B16: MOVIMIENTO DE TIERRAS | C16: =Presupuesto!K172 -> 5025.93 | D16: =IF($C$50=0,0,C16/$C$50) -> 0.012569153
A17: 04 | B17: DRENAJES Y SANEAMIENTO | C17: =Presupuesto!K212 -> 6481.94 | D17: =IF($C$50=0,0,C17/$C$50) -> 0.016210431
A18: 05 | B18: CIMENTACIÓN Y ESTRUCTURA | C18: =Presupuesto!K286 -> 86385.23 | D18: =IF($C$50=0,0,C18/$C$50) -> 0.21603746
A19: 05.01 | B19: CIMENTACIÓN Y FORJADO SANITARIO | C19: =SUMIFS(Presupuesto!$K$5:$K$1399,Presupuesto!$M$5:$M$1399,"P",Presupuesto!$O$5:$O$1399,"05.01") -> 23806.03
A20: 05.02 | B20: ESTRUCTURA | C20: =SUMIFS(Presupuesto!$K$5:$K$1399,Presupuesto!$M$5:$M$1399,"P",Presupuesto!$O$5:$O$1399,"05.02") -> 62579.2
A21: 06 | B21: ALBAÑILERÍA | C21: =Presupuesto!K365 -> 56031.31 | D21: =IF($C$50=0,0,C21/$C$50) -> 0.14012652
A22: 07 | B22: CUBIERTA | C22: =Presupuesto!K422 -> 14386.83 | D22: =IF($C$50=0,0,C22/$C$50) -> 0.035979463
A23: 08 | B23: AISLAMIENTOS, IMPERMEABILIZACIÓN Y SELLADOS | C23: =Presupuesto!K458 -> 7531.54 | D23: =IF($C$50=0,0,C23/$C$50) -> 0.018835335
A24: 09 | B24: FALSOS TECHOS | C24: =Presupuesto!K473 -> 3675.43 | D24: =IF($C$50=0,0,C24/$C$50) -> 0.0091917397
A25: 10 | B25: PAVIMENTOS | C25: =Presupuesto!K514 -> 21764.7 | D25: =IF($C$50=0,0,C25/$C$50) -> 0.05443049
A26: 11 | B26: REVESTIMIENTOS | C26: =Presupuesto!K545 -> 28737.74 | D26: =IF($C$50=0,0,C26/$C$50) -> 0.071869095
A27: 12 | B27: CARPINTERÍA INTERIOR | C27: =Presupuesto!K564 -> 10570.72 | D27: =IF($C$50=0,0,C27/$C$50) -> 0.026435902
A28: 13 | B28: CARPINTERÍA EXTERIOR | C28: =Presupuesto!K632 -> 52569.01 | D28: =IF($C$50=0,0,C28/$C$50) -> 0.13146779
A29: 14 | B29: PROTECCIONES SOLARES, METALISTERÍA Y VIDRIERÍA | C29: =Presupuesto!K664 -> 20509.5 | D29: =IF($C$50=0,0,C29/$C$50) -> 0.05129141
A30: 15 | B30: PINTURA | C30: =Presupuesto!K676 -> 9002.57 | D30: =IF($C$50=0,0,C30/$C$50) -> 0.022514177
A31: 16 | B31: INSTALACIONES | C31: =Presupuesto!K1073 -> 45949.51 | D31: =IF($C$50=0,0,C31/$C$50) -> 0.11491334
A32: 16.01 | B32: FONTANERÍA | C32: =SUMIFS(Presupuesto!$K$5:$K$1399,Presupuesto!$M$5:$M$1399,"P",Presupuesto!$O$5:$O$1399,"16.01") -> 8549.61
A33: 16.02 | B33: CONTRA INCENDIOS | C33: =SUMIFS(Presupuesto!$K$5:$K$1399,Presupuesto!$M$5:$M$1399,"P",Presupuesto!$O$5:$O$1399,"16.02") -> 149.49
A34: 16.03 | B34: CALEFACCIÓN Y A.C.S. | C34: =SUMIFS(Presupuesto!$K$5:$K$1399,Presupuesto!$M$5:$M$1399,"P",Presupuesto!$O$5:$O$1399,"16.03") -> 18015.07
A35: 16.04 | B35: VENTILACIÓN | C35: =SUMIFS(Presupuesto!$K$5:$K$1399,Presupuesto!$M$5:$M$1399,"P",Presupuesto!$O$5:$O$1399,"16.04") -> 4031.5
A36: 16.05 | B36: ELECTRICIDAD E ILUMINACIÓN | C36: =SUMIFS(Presupuesto!$K$5:$K$1399,Presupuesto!$M$5:$M$1399,"P",Presupuesto!$O$5:$O$1399,"16.05") -> 12525.53
A37: 16.06 | B37: TELECOMUNICACIONES | C37: =SUMIFS(Presupuesto!$K$5:$K$1399,Presupuesto!$M$5:$M$1399,"P",Presupuesto!$O$5:$O$1399,"16.06") -> 2678.31
A38: 18 | B38: CONTROL DE CALIDAD | C38: =Presupuesto!K1090 -> 1524.5 | D38: =IF($C$50=0,0,C38/$C$50) -> 0.0038125627
A39: 18.01 | B39: ESTRUCTURAS HORMIGON | C39: =SUMIFS(Presupuesto!$K$5:$K$1399,Presupuesto!$M$5:$M$1399,"P",Presupuesto!$O$5:$O$1399,"18.01") -> 500
A40: 18.02 | B40: ESTUDIO GEOTECNICO | C40: =SUMIFS(Presupuesto!$K$5:$K$1399,Presupuesto!$M$5:$M$1399,"P",Presupuesto!$O$5:$O$1399,"18.02") -> 1024.5
A41: 19 | B41: GESTIÓN DE RESIDUOS | C41: =Presupuesto!K1125 -> 2750.04 | D41: =IF($C$50=0,0,C41/$C$50) -> 0.0068774679
A42: 20 | B42: SEGURIDAD Y SALUD | C42: =Presupuesto!K1397 -> 4095.6 | D42: =IF($C$50=0,0,C42/$C$50) -> 0.010242527
...

Sheet Presupuesto
A1: PRESUPUESTO Y MEDICIONES
A2: DERRIBO Y VIVIENDA DE NUEVA PLANTA · C. ANCHA 34, LODOSA · Presupuesto conjunto (derribo + obra nueva) · propuesta de octubre de 2026
A4: Código | B4: Ud | C4: Resumen | D4: Uds | E4: Longitud | F4: Anchura | G4: Altura | H4: Parcial | I4: Cantidad | J4: Precio | K4: Importe | L4: Origen del precio / observaciones | M4: tipo | N4: cap | O4: sub
A5: D | C5: DERRIBO
A7: D01 | C7: ACTUACIONES PREVIAS, PROTECCIÓN Y APEO DE MEDIANERAS | M7: C | N7: D01
A8: D01.01 | B8: m2 | C8: APEO DE ESTRUCTURA CON MADERA
C9: M². Apeo de estructura con sopandas, puntales y durmientes de madera, hasta una altura de 3 m, i/replanteo y p.P. De costes indirectos.
C10: Fachada norte | D10: 1 | E10: 10 | H10: =IF(COUNT(D10:G10)=0,0,D10*IF(E10="",1,E10)*IF(F10="",1,F10)*IF(G10="",1,G10)) -> 10
C11: Fachada sur | D11: 1 | E11: 10 | H11: =IF(COUNT(D11:G11)=0,0,D11*IF(E11="",1,E11)*IF(F11="",1,F11)*IF(G11="",1,G11)) -> 10
I12: =ROUND(SUM(H10:H11),2) -> 20 | J12: 2.63 | K12: =ROUND(I12*J12,2) -> 52.6 | L12: Importe del documento del proyecto, sin cambios | M12: P | N12: D01
A13: D01.02 | B13: m2 | C13: APEOS DE FACHADA
C14: M2. Estructura superslim para estabilización de fachadas, de rmd kwikform iberica, s.A, consistente en formación de estructura superslim de vigas aligeradas con uniones atornilladas, dicha estructura se une a la fachada mediante las correas superslim exteriores e interiores. La finalidad del sistema es estabilizar la fachada frente a posibles cargas horizontales de viento y 1 % debido a posibles desplomes. Se incluye en el precio el montaje y desmontaje, alquiler, transporte, medios auxiliares, acometidas, hasta una altura máxima de 10 m., I/replanteo y p.P. De costes indirectos. Se incluyen vigas metálicas que pasen los muros y curuzen y den estabilidad a las fachadas. Según criteriorios arquitecto director. Según documentación de los planos de proyecto
C15: Fachada norte | D15: 1 | E15: 10 | H15: =IF(COUNT(D15:G15)=0,0,D15*IF(E15="",1,E15)*IF(F15="",1,F15)*IF(G15="",1,G15)) -> 10
C16: Fachada sur | D16: 1 | E16: 10 | H16: =IF(COUNT(D16:G16)=0,0,D16*IF(E16="",1,E16)*IF(F16="",1,F16)*IF(G16="",1,G16)) -> 10
I17: =ROUND(SUM(H15:H16),2) -> 20 | J17: 45.03 | K17: =ROUND(I17*J17,2) -> 900.6 | L17: Importe del documento del proyecto, sin cambios | M17: P | N17: D01
C18: TOTAL D01 ACTUACIONES PREVIAS, PROTECCIÓN Y APEO DE MEDIANERAS | K18: =SUMIFS($K$5:$K$17,$M$5:$M$17,"P",$N$5:$N$17,"D01") -> 953.2
A20: D02 | C20: DEMOLICIONES | M20: C | N20: D02
A21: D02.01 | B21: ud | C21: DESMONTES Y DEMOLICIONES
C22: Desmontes y demoliciones realizados con medios manuales, mecánico-neumáticos y/o eléctricos, siempre que no afecten a la solidez de los elementos que se proyecta conservar, y siguiendo en todo momento las directrices, procesos, orden y disposiciones previstas en el proyecto, en los apartados correspondientes a desmontes y demoliciones, comprendiendo: - La preparación previa de la obra, vallados, desconexión de acometidas de servicios, retirada de depósitos de todo tipo, desinfección y desinsectación del edificio, montaje de los medios auxiliares, montaje de los elementos de seguridad que eviten la caída o proyección de materiales al exterior, etc., Estando incluido su costo en los gastos generales de la obra excepción hecha de lso que expresamente se consideren en el presente presupuesto; - Los apeos previos que se indican (en su caso) en los planos y memorias, los que se señalen en dirección de obra o los que la urgencia determinen, estando incluido su costo en los gastos generales de la obra excepción hecha de los que expresamente se consideren en el presente presupuesto; - La preparación de la unidad de obra para su demolición, tal como cortes de viguetas para producir la separación física de lo demolible con lo que permanece en pie, etc., - La demolición de la unidad o elemento de que se trate con todo tipo de instalaciones que albergue (tuberías, conductos eléctricos o de aire, entramados secundarios, etc.) Que soporte (radiadores, aparatos sanitarios,espejos, estanterías, armarios, rejillas, luminarias, regletas, accesorios, etc.) Orevestimientos adicionales como azulejos, zócales, molduras; - Los acarreos, contenedores, tolvas; - La carga, transporte a vertedero, descarga y canon de vertido en vertedero autorizado de la totalidad de los productos procedentes de los desmontes y demoliciones; - Los esponjamientos; - Todos cuantos medios auxiliares se necesiten (apeos, cintas continuas, andamiajes, grúas fijas o móviles, maquinaria pesada y colocación y retirada con grúa móvil de gran tonelaje, maquinaria ligera, herramienta, tableros de trabajo o de paso, etc.); - Cuantos medios de protección y seguridad se precisen, tanto los contemplados en el correspondiente estudio o plan de seguridad aprobado (que se abonarán según lo establecido en aquel) como los que se determinen a pie de tajo; - La completa y esmerada limpieza final de la zona de trabajo; - Lo que de concreto para cada unidad se refleja en cada una de las especificaciones que a continuación se desarrollan; - El precio abarcará también la recomposición de fábricas, mochetas o enlaces de los muros medianeros que permanecen ( en el supuesto de que sufrieran deterioros), así como la reposición de los elementos estructurales afectados. Esta nota previa general lo es para todo el presupuesto de desmontes y demoliciones en sus diferentes capítulos y partidas. El criterio de medición se expresa en cada partida, siendo la regla general medir la unidad de obra global de que se trata, según la unidad de medición establecida en cada caso, sin deducciones de huecos y sin incrementos por componentes. Se entiende que el costo total del derribo viene reflejado en las partidas del presupuesto, estando incluido en los gastos generales cualquier otra partida, mano de obra, medio auxiliar, maquinaria, herramienta, materiales, sistemas dea peo, protección y seguridad que fuesen precisos para llevar a cabo la total demolición de lo proyectado bien por el método previsto en el proyecto o bien por la alternativa que previamente se pudiera presentar por el adjudicatario y aprobar por la dirección facultativa.
C23: General | D23: 1 | H23: =IF(COUNT(D23:G23)=0,0,D23*IF(E23="",1,E23)*IF(F23="",1,F23)*IF(G23="",1,G23)) -> 1
I24: =ROUND(SUM(H23:H23),2) -> 1 | J24: 0.86 | K24: =ROUND(I24*J24,2) -> 0.86 | L24: Importe del documento del proyecto, sin cambios | M24: P | N24: D02
A25: D02.02 | B25: ud | C25: NOTA PREVIA DE DERRIBO
C26: Todos los conceptos que a continuación se eneumeran se incluyen dentros los costos generales de la obra son: Señalización y marcaje de todos los tabiques y elementos de derribar, según instrucciones del d.E.O., Señalizaciones en general, replanteos, marcados, compartimentación de zonas, automatización sistemática de los procesos de protección antipolvo, pasos provisionales, cierres provisionales, limpieza diaria de las zonas de trabajo y medidas de seguridad complementarias, derivadas de la necesidad de realizar los trabajos con los pabellones y galerías prestando su función asistencial. Todas las operaciones descritas en este capítulo u otros resultantes por el proceso de obra, se entiende llevarán incorporado en su precio aquellas medidas de apeos, cierres de colindantes y protecciones necesarias para su seguridad y correcta ejecución. Se incluye en el precio de cada partida las medidas de seguridad descritas en el estudio de seguridad y aprobadas por el coordinador de seguridad.
C27: General | D27: 1 | H27: =IF(COUNT(D27:G27)=0,0,D27*IF(E27="",1,E27)*IF(F27="",1,F27)*IF(G27="",1,G27)) -> 1
I28: =ROUND(SUM(H27:H27),2) -> 1 | J28: 0.86 | K28: =ROUND(I28*J28,2) -> 0.86 | L28: Importe del documento del proyecto, sin cambios | M28: P | N28: D02
A29: D02.03 | B29: ud | C29: DESMONTAJE Y TRASLADO MOBILIARIO
C30: Desmontaje del mobiliario existente en la totalidad del edificio incluso armarios empotrados, de acuerdo a cada una de las fases previstas. Traslado del mismo a otras zonas del edificio tantas veces como sea necesario, i/traslado a vertedero de mobiliario que no se pueda reutilizar y canon de vertido. La medición es del total de las obras.
C31: General | D31: 1 | H31: =IF(COUNT(D31:G31)=0,0,D31*IF(E31="",1,E31)*IF(F31="",1,F31)*IF(G31="",1,G31)) -> 1
I32: =ROUND(SUM(H31:H31),2) -> 1 | J32: 607.9 | K32: =ROUND(I32*J32,2) -> 607.9 | L32: Importe del documento del proyecto, sin cambios | M32: P | N32: D02
A33: D02.04 | B33: m | C33: PROTECCION PERIMETRO
C34: Protección del edificio para evitar las proyecciones de materiales procedentes del desmonte o derribos hacia el exterior, a base de marquesina resistente abarcando el conjunto de piezas y elementos portantes (puntales, durmientes, jácenas, tornapuntas y jabalcones, etc) y el tablero o elemento suficientemente resistente para la formación de la marquesina. En ningún momento se permitirá la acumularción de escombro en tal cantidad que ponga el peligro la estabilidad y seguridad de la marquesina, para lo cual se desescombrará cuantas veces sean necesarias y como mínimo una vez al día (al acabar la jornada), previa inspección del personal responsable del adjudicatario adscrito a esta función. Se medirá la longitud de la fachada exterior.
C35: Perímetro | D35: 1 | E35: 58.51 | H35: =IF(COUNT(D35:G35)=0,0,D35*IF(E35="",1,E35)*IF(F35="",1,F35)*IF(G35="",1,G35)) -> 58.51
I36: =ROUND(SUM(H35:H35),2) -> 58.51 | J36: 10.73 | K36: =ROUND(I36*J36,2) -> 627.81 | L36: Importe del documento del proyecto, sin cambios | M36: P | N36: D02
A37: D02.05 | B37: ud | C37: EQUIPO EXTINCIÓN
C38: Conjunto de equipos de extinción que se citan a continuación, como presencias de los mismos en obra y su posible uso y desgaste o consumo en caso de necesidad a lo largo del proceso de derribos y desescombrado, según lo expresado en las notas previas. El conjunto abarca: Cuatro extintores de polvo seco, de 10 dm3 y dos extintores de co2. La presencia se entiende inexcusablemente obligatoria en los tajos abiertos de desmontes y/o demoliciones. Se aleccionará a todo el personal presente en la obra durante la ejecución de este tipo de trabajos sobre el manejo de los extintores, notificación de uso y de desgaste o deterioro, etc .
C39: General | D39: 1 | H39: =IF(COUNT(D39:G39)=0,0,D39*IF(E39="",1,E39)*IF(F39="",1,F39)*IF(G39="",1,G39)) -> 1
I40: =ROUND(SUM(H39:H39),2) -> 1 | J40: 231.44 | K40: =ROUND(I40*J40,2) -> 231.44 | L40: Importe del documento del proyecto, sin cambios | M40: P | N40: D02
A41: D02.06 | B41: ud | C41: DEMOLICIÓN DE CUBIERTAS Y EDIFICIO DE MADERA
C42: Desmontaje integral de la estructura de madera existente, con especial atencion en la cubierta, incluyendo la retirada manual y cuidadosa de todos los elementos estructurales constituyentes: Vigas, pilares, correas y demás componentes de madera, mediante procedimientos que garanticen su integridad y posibiliten su reutilización. Se contempla el aprovechamiento de todos aquellos elementos que se encuentren en estado adecuado para su reincorporación en la nueva estructura, debiendo ser clasificados, acopiados y almacenados en zona seca y protegida para asegurar su correcta conservación hasta el momento de su reinstalación. La intervención comprende la totalidad de la estructura portante de madera del edificio, afectando a todos los niveles o secciones en los que ésta esté presente. La empresa adjudicataria deberá elaborar un informe técnico de desmontaje exhaustivo, documentando la ubicación original de cada uno de los elementos estructurales mediante planos, croquis, esquemas u otros medios gráficos necesarios, con el objeto de permitir su correcta recolocación en la nueva estructura de clt (cross laminated timber) una vez ejecutada. Este informe formará parte de la documentación final de obra.
C43: Cubiertas y estructura de madera | D43: 1 | H43: =IF(COUNT(D43:G43)=0,0,D43*IF(E43="",1,E43)*IF(F43="",1,F43)*IF(G43="",1,G43)) -> 1
...

Sheet Criterios
A1: CRITERIOS
A3: Objeto | B3: Presupuesto conjunto de la actuación en C. Ancha 34, Lodosa: bloque D (Proyecto de Derribo, documento 11) + bloque ON (propuesta de presupuesto del proyecto de ejecución de la vivienda, octubre de 2026). Cada bloque es idéntico a su presupuesto por separado.
A4: Demolición | B4: Va solo en el bloque D. El capítulo 02 de la obra nueva queda como nota (0 €) para no duplicarla.
A5: IVA | B5: IVA: 21 % en el derribo (como en el Proyecto de Derribo) y 10 % en la obra nueva de vivienda (criterio del presupuesto de 24/12/2024). Confirmar con la asesoría.
A6: Precios | B6: Columna «Origen»: (A) presupuesto de 24/12/2024 actualizado un 6 %; (E) referencia de mercado Navarra 2026, contrastar con PREOC / CYPE; (D) importe del documento del proyecto sin cambios. Criterios de medición de la obra nueva: ver su presupuesto por separado.
A7: Presto | B7: El .bc3 lleva los dos bloques como capítulos raíz (D y ON) con sus capítulos dentro.
A8: Modelo BIM (14-oct) | B8: Las partidas de la hoja «Mediciones BIM» se miden en el modelo BIM de Vectorworks generado desde las plantas (muros por tipos con sus capas, forjados, cubiertas, carpinterías, zunchos, pilar y falsos techos). Criterios de Enrique: forjado de viguetas 20+5 en todos los forjados, también el techo del garaje, salvo la terraza de planta segunda, 15+5; barrera de vapor bajo el XPS en la cubierta plana, el patio y el porche (patio y porche acabados a +3,57); no hay cubierta invertida (patio, porche, terraza y cubierta plana: forjado + XPS + antiimpacto 5 mm + mortero de pendientes + lámina de betún modificado + mortero de protección + microcemento exterior); XPS 14 cm en la cubierta plana y 4 cm en el resto; 2,70 m libres en primera y segunda; alicatado hasta 2,28 m y por encima yeso y pintura; zócalo de 0,32 m en fachada y 0,21 m en el resto.
A9: Opción 2 de cubiertas (16-oct) | B9: Enrique 16-oct: se va hacia la opción 2 de cubiertas, así que el presupuesto se mide con ella. Cambia: faldón nuevo sobre la escalera (conecta con la casa de al lado) con el ventanal horizontal de la escalera (alerce, fijo + practicable de 0,60, sustituye al lucernario de aluminio y sus tres estores pasan a uno); la tira junto a la terraza pasa a cubierta plana; faldón de C. del Peso sobre la cubierta plana (17,15 m²), que se mide como los demás faldones (losa, XPS 10, OSB, lámina, rastreles y teja) y deja debajo solo el forjado, sin aislamiento ni acabados de cubierta plana; barandilla de la zona pisable según el croquis y sin la del patio pequeño. El faldón de C. del Peso sobre la cubierta plana es ventilado (Enrique 16-oct): lleva losa, OSB, lámina, rastreles y teja pero no XPS, y el aislamiento (XPS 14 cm con barrera de vapor) y la impermeabilización siguen en la cubierta plana de debajo, que es el suelo del espacio bajo el faldón, donde van la unidad exterior de la aerotermia y un almacenaje. Se cierra con un piñón de Ytong de 20 cm revocado en su cara este (7,47 m², de 0,42 a 2,16 m) y, en el frente que da a la terraza, con una celosía de tramex galvanizado de 2,77 × 1,80 m con un paño fijo y una puerta de 0,80 m del mismo material (14.06); detrás del fijo, la unidad exterior de la aerotermia. El ventanal de la escalera no lleva estor. Los puntos de anclaje junto al lucernario ya no se colocan (07.11 a 0): el ventanal se limpia desde la terraza. DB-HE recalculado con la opción 2 (Anejo 04_2): K ≈ 0,51 < 0,53 y qsol;jul ≈ 1,69 ≤ 2,00.
A10: Opción 3 de cubiertas · IFC final (21-oct) | B10: Enrique 21-oct: el proyecto se cierra con la opción 3 de cubiertas y el presupuesto se mide con el IFC final (lodosa_bim_20261023-0021.ifc, «basico op3»). Cambia respecto a la opción 2: no hay faldón ventilado de C. del Peso, ni celosía de tramex, ni almacenaje en cubierta (14.06 a 0); en la esquina SO, el faldón de C. del Peso sube desde el alero (+9,70) hasta la esquina del patio (+10,295) y desde la limatesa (de la esquina del alero en la medianera oeste a la esquina del patio) un faldón al 21,3 % vierte a la medianera oeste hasta el final del patio, con canalón junto a la medianera (5,67 m en 07.06); la cubierta plana queda en 29,31 m². Cada alero es parte de su faldón (un solo elemento IfcRoof en el IFC), pero vuela 200 mm sin aislamiento (regla de Enrique del 21-oct): losa de Ytong y XPS se miden sin los aleros (82,06 m²); OSB, lámina, rastreles y teja, con ellos (88,37 m²). El lucernario de la escalera es el V12 (2,87 m, alféizar a +9,84 y cabeza en el plano del faldón, de 1,80 a 0,94 m de alto, 3,93 m²); para cumplir el control solar sin estor lleva vidrio de control solar (g ≤ 0,35): sin estor, qsol;jul ≈ 2,30 > 2,00; con el vidrio de control solar, ≈ 1,88. El revoco se mide como piel continua de arriba abajo (310,64 m²: cada plano de fachada es un solo paño, con los cantos de losas y faldones que quedaban vistos, sin contar dos veces lo que se solapaba; huecos descontados, con mochetas y dinteles). La barandilla del borde norte del patio va recta, por detrás de la arista del faldón y no al borde del muro (Enrique 22-oct; 24,08 m en total). La unidad exterior de la aerotermia va en el hueco del muro grueso de la cubierta, junto al V12, ventilada y registrable desde la terraza (Enrique 22-oct); la puerta perforada contigua al V12 está en propuesta (hoja LO-G3b) y todavía no tiene partida. DB-HE recalculado (Anejo 04_2): K ≈ 0,51 < 0,53. Comprobación del IFC: esquema IFC2X3 válido, sin GUID repetidos, 4 plantas, 17 recintos, mediciones en la descripción de cada elemento. Enrique 21-oct 18:50: la geometría de cubiertas sale de su planta de cubiertas (la limatesa va de la esquina del patio a la esquina del alero en la medianera oeste, faldón al 21 %; el borde norte del faldón llega 22 cm más allá). El muro de 45 cm del baño de segunda y de la cocina es de carga de 20 cm con trasdosado de 7 cm (baldosa hacia el baño). Corregido en este IFC respecto al de las 16:58: la junta de las medianeras y la baldosa de los tabiques de baño salen como capas, cada alero va dentro de su faldón, y los 38 muros de segunda cuya fábrica se para bajo el zuncho de coronación se exportan partidos (el muro entero hasta 250 mm por debajo de la coronación más baja y, encima, las capas junto al zuncho y la cuña inclinada, como muros aparte «· coronación» sin medición propia) para que todos los muros lleven su juego de capas; los volúmenes por material no cambian. Quedan, sin efecto en el presupuesto: (1) el nombre del V12 lleva un carácter de control en lugar del guion; (2) las carpinterías no abren hueco en los muros (sin IfcOpeningElement). IFC 22:38 (Enrique 21-oct, «el mortero es continuo»): los paños de revoco del mismo plano forman uno solo (con los cantos de losas y faldones) y la junta de poliestireno de las medianeras solo va contra la casa vecina: donde la medianera asoma por encima del vecino y lleva revoco, no hay junta. IFC 00:51 (22-oct): la barandilla del patio en cubierta pasa por detrás de la arista del faldón (−0,31 m) y la unidad exterior de la aerotermia, al muro grueso junto al V12. IFC 10:29 (22-oct): lleva además las instalaciones (tuberías, conductos, tubos eléctricos y suelo radiante como IfcFlowSegment con su diámetro orientativo y longitud; tomas, mecanismos, puntos de luz y de agua, desagües, bocas, llaves y equipos como IfcFlowTerminal, IfcFlowController…, agrupados por red en IfcSystem), sin medición en este presupuesto. Ventilación (Enrique 21/22-oct): cada boca de extracción lleva rejilla circular vista Ø125 de aluminio anodizado (tipo Mayfe) y extractor silencioso en línea de motor independiente (tipo Soler & Palau) en el falso techo; 10 bocas en los planos LO-H5 y LO-H6, contadas en el modelo 3D (16.04.01, 16.04.02 y 16.05.24); la salida de aire de la cámara Cupolex de planta baja no es boca: la cámara ventila por su propio conducto Ø160 a cubierta (04.06–04.07), independiente de la extracción (Enrique 22-oct; quitado el ramal que la unía a la extracción de planta baja).

Sheet Mediciones BIM
A1: MEDICIONES DEL MODELO BIM FRENTE A LA PROPUESTA DE OCTUBRE
A2: Las partidas de esta hoja toman en la hoja Presupuesto la medición del modelo BIM (Vectorworks, capas BIM-0…BIM-3 del 14 de octubre de 2026; en cubierta, segunda planta y lo que cambia con ella, la opción 3 de cubiertas del IFC final del 21 de octubre). Columna D: medición de la propuesta de octubre (dato fijo). Azul: datos. Verde: enlaces a la hoja Presupuesto. Negro: fórmulas.
A3: Muros: longitud de eje × altura real de cada tramo, sin huecos. Estructura: forjados y zunchos del BIM; cimentación, vigas, pilares y escalera de los planos de estructura LO-E1 a LO-E3 (23-oct). Criterios de Enrique del 14-oct: alicatado hasta 2,28 m, zócalo 0,32/0,21 m, sin cubierta invertida, forjado 20+5 (15+5 en la terraza de segunda), barrera de vapor en cubierta plana, patio y porche, XPS 14 cm en cubierta plana y 4 cm en el resto, 2,70 m libres en primera y segunda.
A5: Código | B5: Ud | C5: Resumen | D5: Medición propuesta oct. | E5: Medición BIM | F5: Diferencia | G5: Dif. % | H5: Precio | I5: Importe propuesta | J5: Importe BIM | K5: Diferencia € | L5: Cómo se mide en el BIM
A6: =Presupuesto!A224 -> 05.01.03 | B6: =Presupuesto!B224 -> m3 | C6: =Presupuesto!C224 -> ZÓCALO DE HORMIGÓN ARMADO HA-25 DE 0,90 M | D6: 20.07 | E6: 27.71 | F6: =E6-D6 -> 7.64 | G6: =IF(D6=0,"-",F6/D6) -> 0.38066766 | H6: =Presupuesto!J227 -> 365.9 | I6: =ROUND(D6*H6,2) -> 7343.61 | J6: =Presupuesto!K227 -> 10139.09 | K6: =J6-I6 -> 2795.48 | L6: Zócalo de 0,90 m bajo los muros de planta baja con el grueso que indica Enrique: 0,32 m en fachada a calle (7.9 m) y 0,21 m de media en el resto (58.5 m). Con el grueso de hormigón de cada muro del BIM sale 12.79 m³ · BIM 24-oct: + muros de hormigón bajo rasante (MC) de la cara superior de la cimentación al suelo de planta baja, 23 tramos, 74,05 m de eje: 14.37 m³ (al precio del zócalo)
A7: =Presupuesto!A232 -> 05.01.05 | B7: =Presupuesto!B232 -> m2 | C7: =Presupuesto!C232 -> FORJADO SANITARIO CUPOLEX CON CAPA DE COMPRESIÓN | D7: 111 | E7: 109.44 | F7: =E7-D7 -> -1.56 | G7: =IF(D7=0,"-",F7/D7) -> -0.014054054 | H7: =Presupuesto!J235 -> 60.2 | I7: =ROUND(D7*H7,2) -> 6682.2 | J7: =Presupuesto!K235 -> 6588.29 | K7: =J7-I7 -> -93.91 | L7: Superficie de estancias y escalera de planta baja (garaje incluido)
A8: =Presupuesto!A237 -> 05.02.01 | B8: =Presupuesto!B237 -> m2 | C8: =Presupuesto!C237 -> FORJADO UNIDIRECCIONAL DE VIGUETAS Y BOVEDILLAS DE EPS 20+5 | D8: 238 | E8: 244.03 | F8: =E8-D8 -> 6.03 | G8: =IF(D8=0,"-",F8/D8) -> 0.025336134 | H8: =Presupuesto!J242 -> 74 | I8: =ROUND(D8*H8,2) -> 17612 | J8: =Presupuesto!K242 -> 18058.22 | K8: =J8-I8 -> 446.22 | L8: Forjado de viguetas 20+5 en todo (Enrique 14-oct), del BIM en proyección con los zunchos de forjado dentro y sin huecos de escalera ni patio: primera 123.4 (con el techo del garaje 53.8) + segunda con la terraza 102.4 + cubierta plana 49.3. El pilar de hormigón junto a la escalera (27×81, tres plantas, 1.87 m³) no tiene partida · Menos la terraza de planta segunda, 11.1 m², que pasa a 15+5 (05.02.11) · Opción 2 de cubiertas (16-oct): la cubierta plana del BIM pasa de 49,3 a 46,47 m² (+11,33 de la tira que deja de ser faldón, −14,17 del faldón nuevo sobre la escalera); los 17,15 m² bajo el faldón nuevo de C. del Peso conservan el forjado · Opción 3 de cubiertas, IFC final (21-oct): la cubierta plana pasa de 46,47 a 30,02 m²; los 16,45 m² restantes son ahora el faldón a la medianera oeste (losa de Ytong), sin forjado: 261,19 − 16,45 · Opción 3, planta de cubiertas de Enrique e IFC 20:01 (21-oct): cubierta plana 29,31 m² (planta de cubiertas de Enrique, 21-oct 18:50): 261,19 − 17,16
A9: =Presupuesto!A243 -> 05.02.02 | B9: =Presupuesto!B243 -> m3 | C9: =Presupuesto!C243 -> VIGAS DE HORMIGÓN ARMADO HA-25 (PLANAS Y DESCOLGADAS) | D9: 0 | E9: 0 | F9: =E9-D9 -> 0 | G9: =IF(D9=0,"-",F9/D9) -> - | H9: =Presupuesto!J246 -> 420 | I9: =ROUND(D9*H9,2) -> 0 | J9: =Presupuesto!K246 -> 8051.4 | K9: =J9-I9 -> 8051.4 | L9: Partida rehecha el 23-oct con la estructura del ingeniero: vigas de hormigón armado de los cuadros de LO-E1/LO-E2 (antes losa maciza del garaje, que ya no existe); no se mide en el BIM
A10: =Presupuesto!A251 -> 05.02.04 | B10: =Presupuesto!B251 -> m | C10: =Presupuesto!C251 -> ZUNCHO DE CORONACIÓN Y DINTEL EN PIEZA U DE YTONG | D10: 198 | E10: 217.99 | F10: =E10-D10 -> 19.99 | G10: =IF(D10=0,"-",F10/D10) -> 0.1009596 | H10: =Presupuesto!J256 -> 46 | I10: =ROUND(D10*H10,2) -> 9108 | J10: =Presupuesto!K256 -> 10027.54 | K10: =J10-I10 -> 919.54 | L10: Zunchos de forjado sobre muros de carga (147.9 m, 14.6 m³) y de coronación bajo cubierta (69.4 m, 3.6 m³, canto supuesto 25 cm) · Opción 2 de cubiertas (16-oct): zunchos remedidos en el BIM de la opción 2 · Opción 3 de cubiertas, IFC final (21-oct): zunchos remedidos en el modelo de la opción 3 · Opción 3, planta de cubiertas de Enrique e IFC 20:01 (21-oct): zunchos remedidos en el modelo de la opción 3 (IFC 20:01)
A11: =Presupuesto!A265 -> 05.02.07 | B11: =Presupuesto!B265 -> m2 | C11: =Presupuesto!C265 -> LOSA ARMADA DE HORMIGÓN CELULAR YTONG PARA CUBIERTA, 25 CM | D11: 70 | E11: 82.06 | F11: =E11-D11 -> 12.06 | G11: =IF(D11=0,"-",F11/D11) -> 0.17228571 | H11: =Presupuesto!J268 -> 108 | I11: =ROUND(D11*H11,2) -> 7560 | J11: =Presupuesto!K268 -> 8862.48 | K11: =J11-I11 -> 1302.48 | L11: Faldones medidos en pendiente (sin aleros, 6.0 m² en planta aparte) · Opción 2 de cubiertas (16-oct): faldones en pendiente 62,44 + faldón sobre la escalera 14,79 + faldón de C. del Peso sobre la cubierta plana 17,90 − tira que pasa a plana 11,84 · Opción 3 de cubiertas, IFC final (21-oct): faldón de C. Ancha 47,37 (con el de la escalera, mismo plano) + faldón de C. del Peso 11,58 + faldón a la medianera oeste 22,28 = 81,23 m² en pendiente, sin los aleros: regla de Enrique del 21-oct, el alero es parte de su faldón pero vuela 200 mm sin aislamiento (no lleva losa de Ytong ni XPS). Ya no hay faldón ventilado · Opción 3, planta de cubiertas de Enrique e IFC 20:01 (21-oct): faldón de C. Ancha 47,38 + faldón de C. del Peso 11,54 + faldón a la medianera oeste 23,14 = 82,06 m² en pendiente, sin los aleros (200 mm sin aislamiento): planta de cubiertas de Enrique del 21-oct (la limatesa va a la esquina del alero en la medianera, faldón oeste al 21 %; su borde norte llega 22 cm más allá)
A12: =Presupuesto!A278 -> 05.02.10 | B12: =Presupuesto!B278 -> kg | C12: =Presupuesto!C278 -> ZANCAS DE PLETINA 200×12 S275 DE LA ESCALERA | D12: 0 | E12: 0 | F12: =E12-D12 -> 0 | G12: =IF(D12=0,"-",F12/D12) -> - | H12: =Presupuesto!J281 -> 3.2 | I12: =ROUND(D12*H12,2) -> 0 | J12: =Presupuesto!K281 -> 1513.6 | K12: =J12-I12 -> 1513.6 | L12: Partida rehecha el 23-oct con la estructura del ingeniero: zancas de la escalera (antes pilar de hormigón 27×81, que pasa a ser el pilar metálico P-6 de 05.02.03); no se mide en el BIM
A13: =Presupuesto!A282 -> 05.02.11 | B13: =Presupuesto!B282 -> m2 | C13: =Presupuesto!C282 -> FORJADO UNIDIRECCIONAL DE VIGUETAS Y BOVEDILLAS DE EPS 15+5 (TERRAZA DE PLANTA SEGUNDA) | D13: 0 | E13: 11.06 | F13: =E13-D13 -> 11.06 | G13: =IF(D13=0,"-",F13/D13) -> - | H13: =Presupuesto!J285 -> 68 | I13: =ROUND(D13*H13,2) -> 0 | J13: =Presupuesto!K285 -> 752.08 | K13: =J13-I13 -> 752.08 | L13: Forjado de la terraza de planta segunda en el BIM (15+5, Enrique 14-oct) · Partida nueva
A14: =Presupuesto!A289 -> 06.01 | B14: =Presupuesto!B289 -> m2 | C14: =Presupuesto!C289 -> FÁBRICA DE HORMIGÓN CELULAR YTONG 30 CM, D350 (FACHADAS) | D14: 85.85 | E14: 81.61 | F14: =E14-D14 -> -4.24 | G14: =IF(D14=0,"-",F14/D14) -> -0.049388468 | H14: =Presupuesto!J299 -> 82 | I14: =ROUND(D14*H14,2) -> 7039.7 | J14: =Presupuesto!K299 -> 6692.02 | K14: =J14-I14 -> -347.68 | L14: Muros M1/M9 de fachada: longitud de eje × altura real de cada tramo, sin huecos ni zócalo · Opción 3 de cubiertas, IFC final (21-oct): −0,71 m²: los muros se acortan o adelgazan 15 mm para dejar paso al revoco continuo · Opción 3, planta de cubiertas de Enrique e IFC 20:01 (21-oct): +0,52 m² de fachada con las dos caras al exterior (M1e) en segunda
A15: =Presupuesto!A300 -> 06.02 | B15: =Presupuesto!B300 -> m2 | C15: =Presupuesto!C300 -> FÁBRICA DE HORMIGÓN CELULAR YTONG 20 CM, D350 (MUROS A PATIO) | D15: 70.54 | E15: 83.8 | F15: =E15-D15 -> 13.26 | G15: =IF(D15=0,"-",F15/D15) -> 0.18797845 | H15: =Presupuesto!J306 -> 58 | I15: =ROUND(D15*H15,2) -> 4091.32 | J15: =Presupuesto!K306 -> 4860.4 | K15: =J15-I15 -> 769.08 | L15: Muros M6/M7/M8/M14 a patio o sin casa pegada · Opción 2 de cubiertas (16-oct): −1,50 m² de muro de quiebro (M7e) que cambia con los faldones nuevos · +13,89 m² de piñones de Ytong 20 cm que cierran el faldón de C. del Peso sobre la cubierta plana (cara norte 2,97 × 2,16 m y cara este 5,81 m de 0,42 a 2,16 m) · Celosía de tramex en el frente del faldón ventilado (Enrique 16-oct): −6,42 m² del piñón norte (2,97 × 2,16 m); queda el piñón este (7,47 m²) · Opción 3 de cubiertas, IFC final (21-oct): sin el faldón ventilado de C. del Peso: −20,86 m² de muros con las dos caras al exterior (M7e) y −11,22 m² de M6/M7 de segunda; +13,73 m² de muros de quiebro (M7c) donde la cubierta alta se junta con la baja · Opción 3, planta de cubiertas de Enrique e IFC 20:01 (21-oct): +0,89 m² de muros exteriores de segunda (M6, M7, M7c, M8) con la planta de cubiertas nueva
A16: =Presupuesto!A307 -> 06.03 | B16: =Presupuesto!B307 -> m2 | C16: =Presupuesto!C307 -> FÁBRICA DE HORMIGÓN CELULAR YTONG 20 CM (MEDIANERAS Y MUROS DE CARGA) | D16: 327.98 | E16: 374.64 | F16: =E16-D16 -> 46.66 | G16: =IF(D16=0,"-",F16/D16) -> 0.14226477 | H16: =Presupuesto!J314 -> 54 | I16: =ROUND(D16*H16,2) -> 17710.92 | J16: =Presupuesto!K314 -> 20230.56 | K16: =J16-I16 -> 2519.64 | L16: Medianeras M2–M5/M10–M12 e interiores de carga M13 · Opción 2 de cubiertas (16-oct): +8,09 m² de medianera M2 que sube hasta el faldón sobre la escalera y +2,54 m² de M13 (muro de la escalera hasta el alféizar del ventanal y dintel encima) · Opción 3 de cubiertas, IFC final (21-oct): +7,09 m² de la medianera M2 que sube hasta el faldón a la medianera oeste, +2,62 m² de muro de carga M13/M13b y −0,37 m² de recortes · Opción 3, planta de cubiertas de Enrique e IFC 20:01 (21-oct): −1,49 m²: el muro de 45 cm del baño de segunda y de la cocina pasa a ser de carga de 20 cm + trasdosado (M13t, Enrique 21-oct), medianeras y muros de carga remedidos
A17: =Presupuesto!A315 -> 06.04 | B17: =Presupuesto!B315 -> m2 | C17: =Presupuesto!C315 -> JUNTA DE POLIESTIRENO EXPANDIDO 10 MM CONTRA MEDIANERA | D17: 350.03 | E17: 328.06 | F17: =E17-D17 -> -21.97 | G17: =IF(D17=0,"-",F17/D17) -> -0.062766049 | H17: =Presupuesto!J320 -> 4.8 | I17: =ROUND(D17*H17,2) -> 1680.14 | J17: =Presupuesto!K320 -> 1574.69 | K17: =J17-I17 -> -105.45 | L17: Capa de junta de los muros de medianera · Opción 2 de cubiertas (16-oct): +8,09 m² de la medianera M2 que sube hasta el faldón sobre la escalera · Opción 3 de cubiertas, IFC final (21-oct): +6,72 m² de junta de las medianeras (la M2 que sube). Se mide con la geometría. En el IFC 1843 la junta sale en todas las medianeras como capa del muro · Opción 3, planta de cubiertas de Enrique e IFC 20:01 (21-oct): −0,23 m² de medianera de segunda (IFC 20:01) · IFC 22:38 (21-oct, mortero continuo): junta solo donde la fábrica va contra la casa vecina: −38,68 m² en los tramos de medianera que asoman por encima del vecino y llevan revoco (oeste de planta baja y primera, segunda sobre V2, V4 y V6)
A18: =Presupuesto!A321 -> 06.05 | B18: =Presupuesto!B321 -> m2 | C18: =Presupuesto!C321 -> TRASDOSADO DE HORMIGÓN CELULAR YTONG 7 CM CON CÁMARA | D18: 83.01 | E18: 99.47 | F18: =E18-D18 -> 16.46 | G18: =IF(D18=0,"-",F18/D18) -> 0.19828936 | H18: =Presupuesto!J326 -> 34 | I18: =ROUND(D18*H18,2) -> 2822.34 | J18: =Presupuesto!K326 -> 3381.98 | K18: =J18-I18 -> 559.64 | L18: Muros M4/M5/M6 (trasdosado de 7 cm con cámara) · Opción 3 de cubiertas, IFC final (21-oct): −2,09 m² (M6 de primera y segunda) · Opción 3, planta de cubiertas de Enrique e IFC 20:01 (21-oct): +3,60 m² del trasdosado del muro de carga del baño de segunda y de la cocina (M13t)
A19: =Presupuesto!A327 -> 06.06 | B19: =Presupuesto!B327 -> m2 | C19: =Presupuesto!C327 -> TABIQUE DE HORMIGÓN CELULAR YTONG 7 CM | D19: 77.47 | E19: 111.98 | F19: =E19-D19 -> 34.51 | G19: =IF(D19=0,"-",F19/D19) -> 0.44546276 | H19: =Presupuesto!J332 -> 33 | I19: =ROUND(D19*H19,2) -> 2556.51 | J19: =Presupuesto!K332 -> 3695.34 | K19: =J19-I19 -> 1138.83 | L19: Tabiques T1/T2/T3 · Opción 2 de cubiertas (16-oct): −2,36 m²: el tabique T2 bajo la tira, que pasa a cubierta plana, es más bajo · Opción 3 de cubiertas, IFC final (21-oct): −0,20 m² de recortes · Opción 3, planta de cubiertas de Enrique e IFC 20:01 (21-oct): +1,80 m² de tabiques de segunda con la planta de cubiertas nueva
A20: =Presupuesto!A340 -> 06.08 | B20: =Presupuesto!B340 -> m | C20: =Presupuesto!C340 -> FRENTE DE FORJADO CON PLAQUETA YTONG Y XPS 4 CM | D20: 62.72 | E20: 43.78 | F20: =E20-D20 -> -18.94 | G20: =IF(D20=0,"-",F20/D20) -> -0.30197704 | H20: =Presupuesto!J344 -> 29 | I20: =ROUND(D20*H20,2) -> 1818.88 | J20: =Presupuesto!K344 -> 1269.62 | K20: =J20-I20 -> -549.26 | L20: Frentes de forjado revestidos en los bordes exteriores de los forjados · Opción 2 de cubiertas (16-oct): +1,87 m de frente de forjado junto a la escalera · Opción 3 de cubiertas, IFC final (21-oct): frentes de forjado remedidos: −5,76 m (la cubierta plana que pasa a faldón y el recorte de 15 mm del revoco) · Opción 3, planta de cubiertas de Enrique e IFC 20:01 (21-oct): frentes de forjado remedidos: −0,80 m
A21: =Presupuesto!A368 -> 07.01 | B21: =Presupuesto!B368 -> m2 | C21: =Presupuesto!C368 -> AISLAMIENTO XPS 10 CM SOBRE LOSA DE CUBIERTA | D21: 70 | E21: 82.06 | F21: =E21-D21 -> 12.06 | G21: =IF(D21=0,"-",F21/D21) -> 0.17228571 | H21: =Presupuesto!J371 -> 17.5 | I21: =ROUND(D21*H21,2) -> 1225 | J21: =Presupuesto!K371 -> 1436.05 | K21: =J21-I21 -> 211.05 | L21: Faldones en pendiente · Opción 2 de cubiertas (16-oct): igual que 05.02.07 · Faldón de C. del Peso ventilado (Enrique 16-oct): sin XPS en sus 17,90 m²; el aislamiento va en la cubierta plana de debajo · Opción 3 de cubiertas, IFC final (21-oct): igual que 05.02.07, sin los aleros: todos los faldones llevan XPS 10 cm (ya no hay faldón ventilado) · Opción 3, planta de cubiertas de Enrique e IFC 20:01 (21-oct): igual que 05.02.07, sin los aleros
A22: =Presupuesto!A384 -> 07.05 | B22: =Presupuesto!B384 -> m² | C22: =Presupuesto!C384 -> COBERTURA DE TEJA CERÁMICA MIXTA | D22: 70 | E22: 88.37 | F22: =E22-D22 -> 18.37 | G22: =IF(D22=0,"-",F22/D22) -> 0.26242857 | H22: =Presupuesto!J387 -> 36.12 | I22: =ROUND(D22*H22,2) -> 2528.4 | J22: =Presupuesto!K387 -> 3191.92 | K22: =J22-I22 -> 663.52 | L22: Faldones en pendiente (los aleros se miden aparte) · Opción 2 de cubiertas (16-oct): igual que 05.02.07 · Opción 3 de cubiertas, IFC final (21-oct): faldones 81,23 m² en pendiente + aleros 6,31 m² (3,17 C. Ancha + 3,02 C. del Peso + 0,12 medianera oeste): la teja, la lámina, el OSB y los rastreles llegan al borde del alero · Opción 3, planta de cubiertas de Enrique e IFC 20:01 (21-oct): faldones 82,06 m² en pendiente + aleros 6,31 m²
A23: =Presupuesto!A402 -> 07.09 | B23: =Presupuesto!B402 -> m2 | C23: =Presupuesto!C402 -> AISLAMIENTO XPS 14 CM EN CUBIERTA PLANA | D23: 77.3 | E23: 29.31 | F23: =E23-D23 -> -47.99 | G23: =IF(D23=0,"-",F23/D23) -> -0.62082794 | H23: =Presupuesto!J405 -> 24.5 | I23: 5720.2 | J23: =Presupuesto!K405 -> 718.1 | K23: =J23-I23 -> -5002.1 | L23: XPS 14 cm de la cubierta plana del BIM (49.3 m²). Sustituye a la cubierta invertida: no hay ninguna (Enrique 14-oct); el resto del paquete está en 05.02.01 (forjado), 08.02 (XPS 4 en patio, porche y terraza), 08.03 (antiimpacto), 07.12 (pendientes), 08.08 (lámina), 10.09 (mortero de protección) y 10.04 (microcemento) · La propuesta medía 77,3 m² de cubierta invertida a 74 €/m² (5.720,20 €) · Opción 2 de cubiertas (16-oct): solo la cubierta plana descubierta: 46,47 − 17,15 m² bajo el faldón de C. del Peso, que lleva el aislamiento en el faldón · Faldón de C. del Peso ventilado (Enrique 16-oct): la cubierta plana bajo él (17,15 m²) lleva el XPS de 14 cm: 29,32 + 17,15 · Opción 3 de cubiertas, IFC final (21-oct): cubierta plana del IFC, 30,02 m² (ya no hay cubierta plana bajo un faldón) · Opción 3, planta de cubiertas de Enrique e IFC 20:01 (21-oct): cubierta plana de la planta de cubiertas de Enrique (21-oct): 29,31 m²
A24: =Presupuesto!A414 -> 07.12 | B24: =Presupuesto!B414 -> m2 | C24: =Presupuesto!C414 -> FORMACIÓN DE PENDIENTES CON MORTERO (1–2 %) EN PATIO, PORCHE, TERRAZA Y CUBIERTA PLANA | D24: 0 | E24: 70.01 | F24: =E24-D24 -> 70.01 | G24: =IF(D24=0,"-",F24/D24) -> - | H24: =Presupuesto!J417 -> 13 | I24: =ROUND(D24*H24,2) -> 0 | J24: =Presupuesto!K417 -> 910.13 | K24: =J24-I24 -> 910.13 | L24: Patio y porche 29.6 + terraza 11.1 + cubierta plana 49.3 m² · Partida nueva · Opción 2 de cubiertas (16-oct): patio y porche 29,6 + terraza 11,1 + cubierta plana descubierta 29,32 m² · Faldón de C. del Peso ventilado (Enrique 16-oct): +17,15 m² bajo el faldón, que es suelo del almacenaje y de la aerotermia · Opción 3 de cubiertas, IFC final (21-oct): patio y porche 29,65 + terraza 11,05 + cubierta plana 30,02 m² · Opción 3, planta de cubiertas de Enrique e IFC 20:01 (21-oct): patio y porche 29,65 + terraza 11,05 + cubierta plana 29,31 m²
A25: =Presupuesto!A418 -> 07.13 | B25: =Presupuesto!B418 -> m2 | C25: =Presupuesto!C418 -> BARRERA DE VAPOR BAJO EL AISLAMIENTO EN CUBIERTA PLANA, PATIO Y PORCHE | D25: 0 | E25: 58.96 | F25: =E25-D25 -> 58.96 | G25: =IF(D25=0,"-",F25/D25) -> - | H25: =Presupuesto!J421 -> 3.8 | I25: =ROUND(D25*H25,2) -> 0 | J25: =Presupuesto!K421 -> 224.05 | K25: =J25-I25 -> 224.05 | L25: Cubierta plana 49.3 + patio y porche 29.6 m² (bajo el XPS) · Partida nueva · Opción 2 de cubiertas (16-oct): cubierta plana descubierta 29,32 + patio y porche 29,6 m² · Faldón de C. del Peso ventilado (Enrique 16-oct): +17,15 m² bajo el faldón · Opción 3 de cubiertas, IFC final (21-oct): cubierta plana 30,02 + patio y porche 29,65 m² · Opción 3, planta de cubiertas de Enrique e IFC 20:01 (21-oct): cubierta plana 29,31 + patio y porche 29,65 m²
A26: =Presupuesto!A425 -> 08.01 | B26: =Presupuesto!B425 -> m2 | C26: =Presupuesto!C425 -> AISLAMIENTO XPS 10 CM SOBRE FORJADO SANITARIO | D26: 60 | E26: 59.92 | F26: =E26-D26 -> -0.08 | G26: =IF(D26=0,"-",F26/D26) -> -0.0013333333 | H26: =Presupuesto!J428 -> 16.5 | I26: =ROUND(D26*H26,2) -> 990 | J26: =Presupuesto!K428 -> 988.68 | K26: =J26-I26 -> -1.32 | L26: Suelo de planta baja dentro de la envolvente (sin garaje)
A27: =Presupuesto!A429 -> 08.02 | B27: =Presupuesto!B429 -> m2 | C27: =Presupuesto!C429 -> XPS 4 CM SOBRE FORJADOS (PASO DE INSTALACIONES) | D27: 163 | E27: 191.09 | F27: =E27-D27 -> 28.09 | G27: =IF(D27=0,"-",F27/D27) -> 0.17233129 | H27: =Presupuesto!J433 -> 7.47 | I27: =ROUND(D27*H27,2) -> 1217.61 | J27: =Presupuesto!K433 -> 1427.44 | K27: =J27-I27 -> 209.83 | L27: XPS 4 cm en todos los forjados: interiores, patio y porche y terraza (la cubierta plana lleva 14 cm, ver 07.09)
A28: =Presupuesto!A434 -> 08.03 | B28: =Presupuesto!B434 -> m2 | C28: =Presupuesto!C434 -> LÁMINA ANTIIMPACTO 5 MM Y BANDA PERIMETRAL | D28: 163 | E28: 220.41 | F28: =E28-D28 -> 57.41 | G28: =IF(D28=0,"-",F28/D28) -> 0.35220859 | H28: =Presupuesto!J437 -> 4.6 | I28: =ROUND(D28*H28,2) -> 749.8 | J28: =Presupuesto!K437 -> 1013.89 | K28: =J28-I28 -> 264.09 | L28: Lámina antiimpacto en todos los forjados: interiores de primera y segunda y también patio y porche, terraza y cubierta plana (Enrique 14-oct) · Opción 2 de cubiertas (16-oct): la cubierta plana bajo el faldón de C. del Peso (17,15 m²) ya no es suelo: 240,4 − 49,3 + 29,32 · Faldón de C. del Peso ventilado (Enrique 16-oct): +17,15 m² bajo el faldón · Opción 3 de cubiertas, IFC final (21-oct): 240,4 − 49,3 + 30,02 (la cubierta plana del IFC) · Opción 3, planta de cubiertas de Enrique e IFC 20:01 (21-oct): 240,4 − 49,3 + 29,31 (la cubierta plana)
A29: =Presupuesto!A454 -> 08.08 | B29: =Presupuesto!B454 -> m2 | C29: =Presupuesto!C454 -> IMPERMEABILIZACIÓN CON LÁMINA DE BETÚN MODIFICADO EN PATIO, PORCHE, TERRAZA Y CUBIERTA PLANA | D29: 0 | E29: 70.01 | F29: =E29-D29 -> 70.01 | G29: =IF(D29=0,"-",F29/D29) -> - | H29: =Presupuesto!J457 -> 22 | I29: =ROUND(D29*H29,2) -> 0 | J29: =Presupuesto!K457 -> 1540.22 | K29: =J29-I29 -> 1540.22 | L29: En planta: patio y porche 29.6 + terraza 11.1 + cubierta plana 49.3 m² (los remontes van en el precio) · Partida nueva · Opción 2 de cubiertas (16-oct): patio y porche 29,6 + terraza 11,1 + cubierta plana descubierta 29,32 m² · Faldón de C. del Peso ventilado (Enrique 16-oct): +17,15 m² bajo el faldón · Opción 3 de cubiertas, IFC final (21-oct): patio y porche 29,65 + terraza 11,05 + cubierta plana 30,02 m² · Opción 3, planta de cubiertas de Enrique e IFC 20:01 (21-oct): patio y porche 29,65 + terraza 11,05 + cubierta plana 29,31 m²
A30: =Presupuesto!A461 -> 09.01 | B30: =Presupuesto!B461 -> m2 | C30: =Presupuesto!C461 -> FALSO TECHO DE PLACA DE YESO LAMINADO 15 MM | D30: 99.35 | E30: 88.49 | F30: =E30-D30 -> -10.86 | G30: =IF(D30=0,"-",F30/D30) -> -0.10931052 | H30: =Presupuesto!J464 -> 27 | I30: =ROUND(D30*H30,2) -> 2682.45 | J30: =Presupuesto!K464 -> 2389.23 | K30: =J30-I30 -> -293.22 | L30: Zonas con trama de la capa «falsos techos», cerradas hasta los muros · Opción 2 de cubiertas (16-oct): +8,52 m² de falso techo plano a +10,50 bajo el faldón de la escalera (cabeza del ventanal) · Opción 3 de cubiertas, IFC final (21-oct): falsos techos del IFC: 88,43 m². Bajo el faldón de la escalera ya no hay falso techo plano (−8,52 m²): el V12 llega hasta el faldón · Opción 3, planta de cubiertas de Enrique e IFC 20:01 (21-oct): falsos techos del IFC 20:01
A31: =Presupuesto!A469 -> 09.03 | B31: =Presupuesto!B469 -> m2 | C31: =Presupuesto!C469 -> TABICA DE PLACA DE YESO LAMINADO EN LOS BORDES DEL FALSO TECHO | D31: 0 | E31: 22.3 | F31: =E31-D31 -> 22.3 | G31: =IF(D31=0,"-",F31/D31) -> - | H31: =Presupuesto!J472 -> 34 | I31: =ROUND(D31*H31,2) -> 0 | J31: =Presupuesto!K472 -> 758.2 | K31: =J31-I31 -> 758.2 | L31: Longitud de los bordes libres del falso techo en el BIM × altura hasta la cara inferior del forjado (0,86 m en baja, 0,42 m en primera y 0,41 m en segunda) · Partida nueva · Opción 3 de cubiertas, IFC final (21-oct): tabicas del IFC: 22,30 m², sin cambios
A32: =Presupuesto!A476 -> 10.01 | B32: =Presupuesto!B476 -> m2 | C32: =Presupuesto!C476 -> MORTERO AUTONIVELANTE DE 4 CM CON SUELO RADIANTE | D32: 188.3 | E32: 210.32 | F32: =E32-D32 -> 22.02 | G32: =IF(D32=0,"-",F32/D32) -> 0.11694105 | H32: =Presupuesto!J479 -> 15 | I32: =ROUND(D32*H32,2) -> 2824.5 | J32: =Presupuesto!K479 -> 3154.8 | K32: =J32-I32 -> 330.3 | L32: Forjados interiores y suelo de planta baja (sin garaje)
A33: =Presupuesto!A484 -> 10.03 | B33: =Presupuesto!B484 -> m2 | C33: =Presupuesto!C484 -> PAVIMENTO CONTINUO DE MICROCEMENTO PULIDO INTERIOR | D33: 191.01 | E33: 192.65 | F33: =E33-D33 -> 1.64 | G33: =IF(D33=0,"-",F33/D33) -> 0.0085859379 | H33: =Presupuesto!J488 -> 48 | I33: =ROUND(D33*H33,2) -> 9168.48 | J33: =Presupuesto!K488 -> 9247.2 | K33: =J33-I33 -> 78.72 | L33: Suelos interiores sin baños ni aseos
A34: =Presupuesto!A489 -> 10.04 | B34: =Presupuesto!B489 -> m2 | C34: =Presupuesto!C489 -> PAVIMENTO CONTINUO DE MICROCEMENTO EXTERIOR | D34: 91.93 | E34: 70.01 | F34: =E34-D34 -> -21.92 | G34: =IF(D34=0,"-",F34/D34) -> -0.23844229 | H34: =Presupuesto!J493 -> 56 | I34: =ROUND(D34*H34,2) -> 5148.08 | J34: =Presupuesto!K493 -> 3920.56 | K34: =J34-I34 -> -1227.52 | L34: Patio y porche, terraza de segunda y terraza en cubierta · Opción 2 de cubiertas (16-oct): patio y porche, terraza de segunda y cubierta plana descubierta 29,32 m² · Faldón de C. del Peso ventilado (Enrique 16-oct): +17,15 m² bajo el faldón (suelo del almacenaje y de la aerotermia) · Opción 3 de cubiertas, IFC final (21-oct): patio y porche, terraza de segunda y cubierta plana 30,02 m² · Opción 3, planta de cubiertas de Enrique e IFC 20:01 (21-oct): patio y porche, terraza de segunda y cubierta plana 29,31 m²
A35: =Presupuesto!A494 -> 10.05 | B35: =Presupuesto!B494 -> m2 | C35: =Presupuesto!C494 -> PAVIMENTO DE GRES PORCELÁNICO EN BAÑOS Y ASEOS | D35: 17.81 | E35: 17.67 | F35: =E35-D35 -> -0.14 | G35: =IF(D35=0,"-",F35/D35) -> -0.0078607524 | H35: =Presupuesto!J497 -> 54 | I35: =ROUND(D35*H35,2) -> 961.74 | J35: =Presupuesto!K497 -> 954.18 | K35: =J35-I35 -> -7.56 | L35: Baños y aseos
A36: =Presupuesto!A498 -> 10.06 | B36: =Presupuesto!B498 -> m2 | C36: =Presupuesto!C498 -> PAVIMENTO CONTINUO DE CUARZO EN GARAJE | D36: 49.52 | E36: 49.52 | F36: =E36-D36 -> 0 | G36: =IF(D36=0,"-",F36/D36) -> 0 | H36: =Presupuesto!J501 -> 15.61 | I36: =ROUND(D36*H36,2) -> 773.01 | J36: =Presupuesto!K501 -> 773.01 | K36: =J36-I36 -> 0 | L36: Garaje
A37: =Presupuesto!A510 -> 10.09 | B37: =Presupuesto!B510 -> m2 | C37: =Presupuesto!C510 -> MORTERO DE PROTECCIÓN DE 4 CM SOBRE LA LÁMINA (PATIO, PORCHE, TERRAZA Y CUBIERTA PLANA) | D37: 0 | E37: 70.01 | F37: =E37-D37 -> 70.01 | G37: =IF(D37=0,"-",F37/D37) -> - | H37: =Presupuesto!J513 -> 15 | I37: =ROUND(D37*H37,2) -> 0 | J37: =Presupuesto!K513 -> 1050.15 | K37: =J37-I37 -> 1050.15 | L37: Patio y porche 29.6 + terraza 11.1 + cubierta plana 49.3 m² · Partida nueva · Opción 2 de cubiertas (16-oct): patio y porche 29,6 + terraza 11,1 + cubierta plana descubierta 29,32 m² · Faldón de C. del Peso ventilado (Enrique 16-oct): +17,15 m² bajo el faldón · Opción 3 de cubiertas, IFC final (21-oct): patio y porche 29,65 + terraza 11,05 + cubierta plana 30,02 m² · Opción 3, planta de cubiertas de Enrique e IFC 20:01 (21-oct): patio y porche 29,65 + terraza 11,05 + cubierta plana 29,31 m²
A38: =Presupuesto!A517 -> 11.01 | B38: =Presupuesto!B517 -> m² | C38: =Presupuesto!C517 -> REVOCO DE CAL / MONOCAPA EN FACHADAS Y PATIOS | D38: 196.3 | E38: 316.1 | F38: =E38-D38 -> 119.8 | G38: =IF(D38=0,"-",F38/D38) -> 0.61029037 | H38: =Presupuesto!J522 -> 29.56 | I38: =ROUND(D38*H38,2) -> 5802.63 | J38: =Presupuesto!K522 -> 9343.92 | K38: =J38-I38 -> 3541.29 | L38: Caras revocadas de muros exteriores y frentes de forjado · Opción 2 de cubiertas (16-oct): −1,50 m² de muro de quiebro y +0,68 m² de frente de forjado · +13,89 m² de los piñones del faldón de C. del Peso · Celosía de tramex en el frente del faldón ventilado (Enrique 16-oct): −6,42 m² del piñón norte · Opción 3 de cubiertas, IFC final (21-oct): revoco continuo del IFC (piel vista de la casa, 34 paños de arriba abajo, regla de Enrique del 19 y 21-oct): caras 289,80 m² con los huecos descontados + mochetas y dinteles 18,68 m²; sin medianeras, bajo aleros ni zócalo. Sustituye a la medición por caras de muro (261,81) · Opción 3, planta de cubiertas de Enrique e IFC 20:01 (21-oct): revoco continuo del IFC 20:01: paños de fachada 308,86 m² + cantos de losas y faldones que quedaban vistos 13,43 m² (patinillo, bordes de la cubierta plana, terraza de segunda, faldones sobre la terraza; Enrique 21-oct: el mortero es continuo) · IFC 22:38 (21-oct, mortero continuo): revoco continuo del IFC 22:38: cada plano de fachada es un solo paño, con los cantos de losas y faldones que quedaban vistos (cara 291,79 m² + mochetas y dinteles 18,85 m²); −11,65 m² respecto al IFC 20:01, que contaba dos veces los cantos tapados por el paño · IFC 24-oct 11:33–11:50 (captura «mortero»): revoco de la cámara bajo el faldón C. del Peso (5,39 m²), esquinas cerradas y pared del patio en un solo paño: 316.10 m²
A39: =Presupuesto!A523 -> 11.02 | B39: =Presupuesto!B523 -> m2 | C39: =Presupuesto!C523 -> GUARNECIDO Y ENLUCIDO DE YESO EN PAREDES Y TECHOS | D39: 701.6 | E39: 950.13 | F39: =E39-D39 -> 248.53 | G39: =IF(D39=0,"-",F39/D39) -> 0.35423318 | H39: =Presupuesto!J532 -> 14 | I39: =ROUND(D39*H39,2) -> 9822.4 | J39: =Presupuesto!K532 -> 13301.82 | K39: =J39-I39 -> 3479.42 | L39: Paredes 726.4 m² (incluye 27.6 m² de baños y aseos por encima de 2,28 m) y techos sin falso techo 214.4 m² · Opción 2 de cubiertas (16-oct): paredes: +8,09 medianera M2, +5,08 muro M13 (dos caras), −4,72 tabique T2 (dos caras), −1,50 quiebro; techos: −8,52 m² que pasan a falso techo · Opción 3 de cubiertas, IFC final (21-oct): paredes −0,80 m² (cambios de muros de segunda) y techos +8,89 m²: bajo el faldón de la escalera ya no hay falso techo (+8,52) y el faldón a la medianera oeste tiene más superficie en pendiente que la cubierta plana a la que sustituye (+0,37) · Opción 3, planta de cubiertas de Enrique e IFC 20:01 (21-oct): +2,84 m² de yeso en paredes (muros de segunda remedidos y trasdosado M13t)
A40: =Presupuesto!A533 -> 11.03 | B40: =Presupuesto!B533 -> m2 | C40: =Presupuesto!C533 -> ALICATADO CERÁMICO 10 MM EN BAÑOS Y ASEOS | D40: 67.81 | E40: 88.02 | F40: =E40-D40 -> 20.21 | G40: =IF(D40=0,"-",F40/D40) -> 0.29803864 | H40: =Presupuesto!J540 -> 64 | I40: =ROUND(D40*H40,2) -> 4339.84 | J40: =Presupuesto!K540 -> 5633.28 | K40: =J40-I40 -> 1293.44 | L40: Caras de baños y aseos con baldosa hasta 2,28 m (por encima, yeso y pintura) · Opción 3 de cubiertas, IFC final (21-oct): +1,06 m² del muro M13b del baño de segunda (hasta 2,28 m). Se mide con la geometría. En el IFC 1843 la baldosa sale en los tabiques de baño (T2, M13b) · Opción 3, planta de cubiertas de Enrique e IFC 20:01 (21-oct): −0,56 m² de baldosa (pared del baño de segunda: muro de carga + trasdosado)
A41: =Presupuesto!A548 -> 12.01 | B41: =Presupuesto!B548 -> ud | C41: =Presupuesto!C548 -> PUERTA DE PASO P2 ENRASADA 0,85 × 2,05 | D41: 7 | E41: 8 | F41: =E41-D41 -> 1 | G41: =IF(D41=0,"-",F41/D41) -> 0.14285714 | H41: =Presupuesto!J551 -> 899.66 | I41: =ROUND(D41*H41,2) -> 6297.62 | J41: =Presupuesto!K551 -> 7197.28 | K41: =J41-I41 -> 899.66 | L41: P2 del BIM (7) + P5 de la Habitación 3, provisional (1)
...
